{
 "cells": [
  {
   "cell_type": "code",
   "execution_count": null,
   "metadata": {},
   "outputs": [
    {
     "name": "stdout",
     "output_type": "stream",
     "text": [
      "The sql extension is already loaded. To reload it, use:\n",
      "  %reload_ext sql\n",
      "Traceback (most recent call last):\n",
      "  File \"c:\\Users\\varun\\AppData\\Local\\Programs\\Python\\Python312\\Lib\\site-packages\\sqlalchemy\\engine\\base.py\", line 146, in __init__\n",
      "    self._dbapi_connection = engine.raw_connection()\n",
      "                             ^^^^^^^^^^^^^^^^^^^^^^^\n",
      "  File \"c:\\Users\\varun\\AppData\\Local\\Programs\\Python\\Python312\\Lib\\site-packages\\sqlalchemy\\engine\\base.py\", line 3302, in raw_connection\n",
      "    return self.pool.connect()\n",
      "           ^^^^^^^^^^^^^^^^^^^\n",
      "  File \"c:\\Users\\varun\\AppData\\Local\\Programs\\Python\\Python312\\Lib\\site-packages\\sqlalchemy\\pool\\base.py\", line 449, in connect\n",
      "    return _ConnectionFairy._checkout(self)\n",
      "           ^^^^^^^^^^^^^^^^^^^^^^^^^^^^^^^^\n",
      "  File \"c:\\Users\\varun\\AppData\\Local\\Programs\\Python\\Python312\\Lib\\site-packages\\sqlalchemy\\pool\\base.py\", line 1263, in _checkout\n",
      "    fairy = _ConnectionRecord.checkout(pool)\n",
      "            ^^^^^^^^^^^^^^^^^^^^^^^^^^^^^^^^\n",
      "  File \"c:\\Users\\varun\\AppData\\Local\\Programs\\Python\\Python312\\Lib\\site-packages\\sqlalchemy\\pool\\base.py\", line 712, in checkout\n",
      "    rec = pool._do_get()\n",
      "          ^^^^^^^^^^^^^^\n",
      "  File \"c:\\Users\\varun\\AppData\\Local\\Programs\\Python\\Python312\\Lib\\site-packages\\sqlalchemy\\pool\\impl.py\", line 179, in _do_get\n",
      "    with util.safe_reraise():\n",
      "  File \"c:\\Users\\varun\\AppData\\Local\\Programs\\Python\\Python312\\Lib\\site-packages\\sqlalchemy\\util\\langhelpers.py\", line 146, in __exit__\n",
      "    raise exc_value.with_traceback(exc_tb)\n",
      "  File \"c:\\Users\\varun\\AppData\\Local\\Programs\\Python\\Python312\\Lib\\site-packages\\sqlalchemy\\pool\\impl.py\", line 177, in _do_get\n",
      "    return self._create_connection()\n",
      "           ^^^^^^^^^^^^^^^^^^^^^^^^^\n",
      "  File \"c:\\Users\\varun\\AppData\\Local\\Programs\\Python\\Python312\\Lib\\site-packages\\sqlalchemy\\pool\\base.py\", line 390, in _create_connection\n",
      "    return _ConnectionRecord(self)\n",
      "           ^^^^^^^^^^^^^^^^^^^^^^^\n",
      "  File \"c:\\Users\\varun\\AppData\\Local\\Programs\\Python\\Python312\\Lib\\site-packages\\sqlalchemy\\pool\\base.py\", line 674, in __init__\n",
      "    self.__connect()\n",
      "  File \"c:\\Users\\varun\\AppData\\Local\\Programs\\Python\\Python312\\Lib\\site-packages\\sqlalchemy\\pool\\base.py\", line 900, in __connect\n",
      "    with util.safe_reraise():\n",
      "  File \"c:\\Users\\varun\\AppData\\Local\\Programs\\Python\\Python312\\Lib\\site-packages\\sqlalchemy\\util\\langhelpers.py\", line 146, in __exit__\n",
      "    raise exc_value.with_traceback(exc_tb)\n",
      "  File \"c:\\Users\\varun\\AppData\\Local\\Programs\\Python\\Python312\\Lib\\site-packages\\sqlalchemy\\pool\\base.py\", line 896, in __connect\n",
      "    self.dbapi_connection = connection = pool._invoke_creator(self)\n",
      "                                         ^^^^^^^^^^^^^^^^^^^^^^^^^^\n",
      "  File \"c:\\Users\\varun\\AppData\\Local\\Programs\\Python\\Python312\\Lib\\site-packages\\sqlalchemy\\engine\\create.py\", line 643, in connect\n",
      "    return dialect.connect(*cargs, **cparams)\n",
      "           ^^^^^^^^^^^^^^^^^^^^^^^^^^^^^^^^^^\n",
      "  File \"c:\\Users\\varun\\AppData\\Local\\Programs\\Python\\Python312\\Lib\\site-packages\\sqlalchemy\\engine\\default.py\", line 621, in connect\n",
      "    return self.loaded_dbapi.connect(*cargs, **cparams)\n",
      "           ^^^^^^^^^^^^^^^^^^^^^^^^^^^^^^^^^^^^^^^^^^^^\n",
      "  File \"c:\\Users\\varun\\AppData\\Local\\Programs\\Python\\Python312\\Lib\\site-packages\\pymysql\\connections.py\", line 361, in __init__\n",
      "    self.connect()\n",
      "  File \"c:\\Users\\varun\\AppData\\Local\\Programs\\Python\\Python312\\Lib\\site-packages\\pymysql\\connections.py\", line 669, in connect\n",
      "    self._request_authentication()\n",
      "  File \"c:\\Users\\varun\\AppData\\Local\\Programs\\Python\\Python312\\Lib\\site-packages\\pymysql\\connections.py\", line 979, in _request_authentication\n",
      "    auth_packet = _auth.caching_sha2_password_auth(self, auth_packet)\n",
      "                  ^^^^^^^^^^^^^^^^^^^^^^^^^^^^^^^^^^^^^^^^^^^^^^^^^^^\n",
      "  File \"c:\\Users\\varun\\AppData\\Local\\Programs\\Python\\Python312\\Lib\\site-packages\\pymysql\\_auth.py\", line 241, in caching_sha2_password_auth\n",
      "    pkt = conn._read_packet()\n",
      "          ^^^^^^^^^^^^^^^^^^^\n",
      "  File \"c:\\Users\\varun\\AppData\\Local\\Programs\\Python\\Python312\\Lib\\site-packages\\pymysql\\connections.py\", line 775, in _read_packet\n",
      "    packet.raise_for_error()\n",
      "  File \"c:\\Users\\varun\\AppData\\Local\\Programs\\Python\\Python312\\Lib\\site-packages\\pymysql\\protocol.py\", line 219, in raise_for_error\n",
      "    err.raise_mysql_exception(self._data)\n",
      "  File \"c:\\Users\\varun\\AppData\\Local\\Programs\\Python\\Python312\\Lib\\site-packages\\pymysql\\err.py\", line 150, in raise_mysql_exception\n",
      "    raise errorclass(errno, errval)\n",
      "pymysql.err.OperationalError: (1049, \"Unknown database 'ads_2024'\")\n",
      "\n",
      "The above exception was the direct cause of the following exception:\n",
      "\n",
      "Traceback (most recent call last):\n",
      "  File \"c:\\Users\\varun\\AppData\\Local\\Programs\\Python\\Python312\\Lib\\site-packages\\sql\\magic.py\", line 196, in execute\n",
      "    conn = sql.connection.Connection.set(\n",
      "           ^^^^^^^^^^^^^^^^^^^^^^^^^^^^^^\n",
      "  File \"c:\\Users\\varun\\AppData\\Local\\Programs\\Python\\Python312\\Lib\\site-packages\\sql\\connection.py\", line 70, in set\n",
      "    cls.current = existing or Connection(descriptor, connect_args, creator)\n",
      "                              ^^^^^^^^^^^^^^^^^^^^^^^^^^^^^^^^^^^^^^^^^^^^^\n",
      "  File \"c:\\Users\\varun\\AppData\\Local\\Programs\\Python\\Python312\\Lib\\site-packages\\sql\\connection.py\", line 55, in __init__\n",
      "    self.internal_connection = engine.connect()\n",
      "                               ^^^^^^^^^^^^^^^^\n",
      "  File \"c:\\Users\\varun\\AppData\\Local\\Programs\\Python\\Python312\\Lib\\site-packages\\sqlalchemy\\engine\\base.py\", line 3278, in connect\n",
      "    return self._connection_cls(self)\n",
      "           ^^^^^^^^^^^^^^^^^^^^^^^^^^\n",
      "  File \"c:\\Users\\varun\\AppData\\Local\\Programs\\Python\\Python312\\Lib\\site-packages\\sqlalchemy\\engine\\base.py\", line 148, in __init__\n",
      "    Connection._handle_dbapi_exception_noconnection(\n",
      "  File \"c:\\Users\\varun\\AppData\\Local\\Programs\\Python\\Python312\\Lib\\site-packages\\sqlalchemy\\engine\\base.py\", line 2442, in _handle_dbapi_exception_noconnection\n",
      "    raise sqlalchemy_exception.with_traceback(exc_info[2]) from e\n",
      "  File \"c:\\Users\\varun\\AppData\\Local\\Programs\\Python\\Python312\\Lib\\site-packages\\sqlalchemy\\engine\\base.py\", line 146, in __init__\n",
      "    self._dbapi_connection = engine.raw_connection()\n",
      "                             ^^^^^^^^^^^^^^^^^^^^^^^\n",
      "  File \"c:\\Users\\varun\\AppData\\Local\\Programs\\Python\\Python312\\Lib\\site-packages\\sqlalchemy\\engine\\base.py\", line 3302, in raw_connection\n",
      "    return self.pool.connect()\n",
      "           ^^^^^^^^^^^^^^^^^^^\n",
      "  File \"c:\\Users\\varun\\AppData\\Local\\Programs\\Python\\Python312\\Lib\\site-packages\\sqlalchemy\\pool\\base.py\", line 449, in connect\n",
      "    return _ConnectionFairy._checkout(self)\n",
      "           ^^^^^^^^^^^^^^^^^^^^^^^^^^^^^^^^\n",
      "  File \"c:\\Users\\varun\\AppData\\Local\\Programs\\Python\\Python312\\Lib\\site-packages\\sqlalchemy\\pool\\base.py\", line 1263, in _checkout\n",
      "    fairy = _ConnectionRecord.checkout(pool)\n",
      "            ^^^^^^^^^^^^^^^^^^^^^^^^^^^^^^^^\n",
      "  File \"c:\\Users\\varun\\AppData\\Local\\Programs\\Python\\Python312\\Lib\\site-packages\\sqlalchemy\\pool\\base.py\", line 712, in checkout\n",
      "    rec = pool._do_get()\n",
      "          ^^^^^^^^^^^^^^\n",
      "  File \"c:\\Users\\varun\\AppData\\Local\\Programs\\Python\\Python312\\Lib\\site-packages\\sqlalchemy\\pool\\impl.py\", line 179, in _do_get\n",
      "    with util.safe_reraise():\n",
      "  File \"c:\\Users\\varun\\AppData\\Local\\Programs\\Python\\Python312\\Lib\\site-packages\\sqlalchemy\\util\\langhelpers.py\", line 146, in __exit__\n",
      "    raise exc_value.with_traceback(exc_tb)\n",
      "  File \"c:\\Users\\varun\\AppData\\Local\\Programs\\Python\\Python312\\Lib\\site-packages\\sqlalchemy\\pool\\impl.py\", line 177, in _do_get\n",
      "    return self._create_connection()\n",
      "           ^^^^^^^^^^^^^^^^^^^^^^^^^\n",
      "  File \"c:\\Users\\varun\\AppData\\Local\\Programs\\Python\\Python312\\Lib\\site-packages\\sqlalchemy\\pool\\base.py\", line 390, in _create_connection\n",
      "    return _ConnectionRecord(self)\n",
      "           ^^^^^^^^^^^^^^^^^^^^^^^\n",
      "  File \"c:\\Users\\varun\\AppData\\Local\\Programs\\Python\\Python312\\Lib\\site-packages\\sqlalchemy\\pool\\base.py\", line 674, in __init__\n",
      "    self.__connect()\n",
      "  File \"c:\\Users\\varun\\AppData\\Local\\Programs\\Python\\Python312\\Lib\\site-packages\\sqlalchemy\\pool\\base.py\", line 900, in __connect\n",
      "    with util.safe_reraise():\n",
      "  File \"c:\\Users\\varun\\AppData\\Local\\Programs\\Python\\Python312\\Lib\\site-packages\\sqlalchemy\\util\\langhelpers.py\", line 146, in __exit__\n",
      "    raise exc_value.with_traceback(exc_tb)\n",
      "  File \"c:\\Users\\varun\\AppData\\Local\\Programs\\Python\\Python312\\Lib\\site-packages\\sqlalchemy\\pool\\base.py\", line 896, in __connect\n",
      "    self.dbapi_connection = connection = pool._invoke_creator(self)\n",
      "                                         ^^^^^^^^^^^^^^^^^^^^^^^^^^\n",
      "  File \"c:\\Users\\varun\\AppData\\Local\\Programs\\Python\\Python312\\Lib\\site-packages\\sqlalchemy\\engine\\create.py\", line 643, in connect\n",
      "    return dialect.connect(*cargs, **cparams)\n",
      "           ^^^^^^^^^^^^^^^^^^^^^^^^^^^^^^^^^^\n",
      "  File \"c:\\Users\\varun\\AppData\\Local\\Programs\\Python\\Python312\\Lib\\site-packages\\sqlalchemy\\engine\\default.py\", line 621, in connect\n",
      "    return self.loaded_dbapi.connect(*cargs, **cparams)\n",
      "           ^^^^^^^^^^^^^^^^^^^^^^^^^^^^^^^^^^^^^^^^^^^^\n",
      "  File \"c:\\Users\\varun\\AppData\\Local\\Programs\\Python\\Python312\\Lib\\site-packages\\pymysql\\connections.py\", line 361, in __init__\n",
      "    self.connect()\n",
      "  File \"c:\\Users\\varun\\AppData\\Local\\Programs\\Python\\Python312\\Lib\\site-packages\\pymysql\\connections.py\", line 669, in connect\n",
      "    self._request_authentication()\n",
      "  File \"c:\\Users\\varun\\AppData\\Local\\Programs\\Python\\Python312\\Lib\\site-packages\\pymysql\\connections.py\", line 979, in _request_authentication\n",
      "    auth_packet = _auth.caching_sha2_password_auth(self, auth_packet)\n",
      "                  ^^^^^^^^^^^^^^^^^^^^^^^^^^^^^^^^^^^^^^^^^^^^^^^^^^^\n",
      "  File \"c:\\Users\\varun\\AppData\\Local\\Programs\\Python\\Python312\\Lib\\site-packages\\pymysql\\_auth.py\", line 241, in caching_sha2_password_auth\n",
      "    pkt = conn._read_packet()\n",
      "          ^^^^^^^^^^^^^^^^^^^\n",
      "  File \"c:\\Users\\varun\\AppData\\Local\\Programs\\Python\\Python312\\Lib\\site-packages\\pymysql\\connections.py\", line 775, in _read_packet\n",
      "    packet.raise_for_error()\n",
      "  File \"c:\\Users\\varun\\AppData\\Local\\Programs\\Python\\Python312\\Lib\\site-packages\\pymysql\\protocol.py\", line 219, in raise_for_error\n",
      "    err.raise_mysql_exception(self._data)\n",
      "  File \"c:\\Users\\varun\\AppData\\Local\\Programs\\Python\\Python312\\Lib\\site-packages\\pymysql\\err.py\", line 150, in raise_mysql_exception\n",
      "    raise errorclass(errno, errval)\n",
      "sqlalchemy.exc.OperationalError: (pymysql.err.OperationalError) (1049, \"Unknown database 'ads_2024'\")\n",
      "(Background on this error at: https://sqlalche.me/e/20/e3q8)\n",
      "\n",
      "Connection info needed in SQLAlchemy format, example:\n",
      "               postgresql://username:password@hostname/dbname\n",
      "               or an existing connection: dict_keys([])\n"
     ]
    }
   ],
   "source": [
    "import pandas as pd\n",
    "import osmnx as ox\n",
    "import shapely as shp\n",
    "import numpy as np\n",
    "import os\n",
    "import requests\n",
    "import fynesse\n",
    "import geopandas as gpd\n",
    "import yaml\n",
    "import matplotlib.pyplot as plt\n",
    "import seaborn as sns\n",
    "from zipfile import ZipFile\n",
    "import sklearn\n",
    "\n",
    "%load_ext sql\n",
    "\n",
    "with open(\"./credentials1.yaml\") as file:\n",
    "  credentials = yaml.safe_load(file)\n",
    "username = credentials[\"username\"]\n",
    "password = credentials[\"password\"]\n",
    "url = credentials[\"url\"]\n",
    "port = credentials[\"port\"]\n",
    "\n",
    "%config SqlMagic.style = '_DEPRECATED_DEFAULT'"
   ]
  },
  {
   "cell_type": "code",
   "execution_count": null,
   "metadata": {},
   "outputs": [],
   "source": []
  },
  {
   "cell_type": "code",
   "execution_count": null,
   "metadata": {},
   "outputs": [
    {
     "name": "stdout",
     "output_type": "stream",
     "text": [
      " * mysql+pymysql://root:***@localhost:3306/ads_2024?local_infile=1\n",
      "0 rows affected.\n",
      " * mysql+pymysql://root:***@localhost:3306/ads_2024?local_infile=1\n",
      "0 rows affected.\n"
     ]
    },
    {
     "data": {
      "text/html": [
       "<table>\n",
       "    <thead>\n",
       "        <tr>\n",
       "            <th>Tables_in_ads_2024</th>\n",
       "        </tr>\n",
       "    </thead>\n",
       "    <tbody>\n",
       "    </tbody>\n",
       "</table>"
      ],
      "text/plain": [
       "[]"
      ]
     },
     "execution_count": 14,
     "metadata": {},
     "output_type": "execute_result"
    }
   ],
   "source": []
  },
  {
   "cell_type": "code",
   "execution_count": null,
   "metadata": {},
   "outputs": [],
   "source": []
  }
 ],
 "metadata": {
  "kernelspec": {
   "display_name": "Python 3",
   "language": "python",
   "name": "python3"
  },
  "language_info": {
   "codemirror_mode": {
    "name": "ipython",
    "version": 3
   },
   "file_extension": ".py",
   "mimetype": "text/x-python",
   "name": "python",
   "nbconvert_exporter": "python",
   "pygments_lexer": "ipython3",
   "version": "3.12.3"
  }
 },
 "nbformat": 4,
 "nbformat_minor": 2
}
